Workbook

Sheet README
A1: RAMANADHAPURAM — First Floor Parametric Modelling Table
A2: Purpose: one row per item of the rev 3 luxury furnishing table (259 items, 14 spaces). A parametric script reads the Items + Placements sheets and calls the generator named for each family to build the mesh, then places every instance.
A4: UNITS & AXES
A5: All dimensions and positions in millimetres. X/Y = plan coordinates on the same grid as the ground floor (origin = building bottom-left outer corner, X east, Y north).
A6: Z is measured from the first-floor finished floor level (FFL = 0). Assumption: FF FFL = +3348 mm above GF FFL (top of the 300 mm GF roof slab); add the screed / finish build-up in the script (FFL_OFFSET).
A7: Rot_Z_deg: rotation of the item about Z so its front faces the listed direction. Convention: local front = +Y; N = 0°, W = 90°, S = 180°, E = 270°. "—" = symmetric / no front.
A8: Pivot rule (UE ready): floor items = bottom-centre; wall items = back-centre on the wall face; ceiling items = top-centre at the mount point; room-wide finishes = room polygon.
A10: SHEETS
A11: Items — 259 rows, exact rev 3 wording, family, generator, size, parameters (JSON), materials, position, orientation, detailed build description, UE naming, Nanite / LOD guidance.
A12: Placements — one row per placed instance (items with pairs/sets have several rows) with its own centre and footprint; the script loops this sheet to place meshes.
A13: Families — the parametric family library: generator function, host type, default height, default parameters (JSON) and the construction recipe. "Items using" is a live COUNTIF.
A14: Materials — M_ material library with base colour, roughness, metallic and texture notes. "Used by items" is a live COUNTIF.
... A29: Items & wording: RMD_FF_Unified_Furnishing_Table_rev3_Luxury.pdf · positions & footprints: RMD_FF_Furnishing_Layout_Set_rev2.pdf (plan traced from the client screenshot, ±20 mm). Heights and parameter defaults are design assumptions — adjust in blue cells.

Sheet Summary
A1: Space | B1: Furniture | C1: Décor | D1: Finish | E1: Lighting / textile | F1: Total (live) | G1: Rev 3 table items | H1: Check
A2: Upper lounge | B2: =COUNTIFS(Items!$B:$B,$A2,Items!$C:$C,"Furniture") -> 8 | C2: =COUNTIFS(Items!$B:$B,$A2,Items!$C:$C,"Décor") -> 7 | D2: =COUNTIFS(Items!$B:$B,$A2,Items!$C:$C,"Finish") -> 6 | E2: =COUNTIFS(Items!$B:$B,$A2,Items!$C:$C,"Lighting / textile") -> 7 | F2: =SUM(B2:E2) -> 28 | G2: 28 | H2: =IF(F2=G2,"OK","MISMATCH") -> OK
A3: Void over GF lounge | B3: =COUNTIFS(Items!$B:$B,$A3,Items!$C:$C,"Furniture") -> 1 | C3: =COUNTIFS(Items!$B:$B,$A3,Items!$C:$C,"Décor") -> 2 | D3: =COUNTIFS(Items!$B:$B,$A3,Items!$C:$C,"Finish") -> 2 | E3: =COUNTIFS(Items!$B:$B,$A3,Items!$C:$C,"Lighting / textile") -> 3 | F3: =SUM(B3:E3) -> 8 | G3: 8 | H3: =IF(F3=G3,"OK","MISMATCH") -> OK
A4: Master bedroom | B4: =COUNTIFS(Items!$B:$B,$A4,Items!$C:$C,"Furniture") -> 7 | C4: =COUNTIFS(Items!$B:$B,$A4,Items!$C:$C,"Décor") -> 7 | D4: =COUNTIFS(Items!$B:$B,$A4,Items!$C:$C,"Finish") -> 5 | E4: =COUNTIFS(Items!$B:$B,$A4,Items!$C:$C,"Lighting / textile") -> 8 | F4: =SUM(B4:E4) -> 27 | G4: 27 | H4: =IF(F4=G4,"OK","MISMATCH") -> OK
A5: Master walk-in wardrobe | B5: =COUNTIFS(Items!$B:$B,$A5,Items!$C:$C,"Furniture") -> 8 | C5: =COUNTIFS(Items!$B:$B,$A5,Items!$C:$C,"Décor") -> 5 | D5: =COUNTIFS(Items!$B:$B,$A5,Items!$C:$C,"Finish") -> 4 | E5: =COUNTIFS(Items!$B:$B,$A5,Items!$C:$C,"Lighting / textile") -> 4 | F5: =SUM(B5:E5) -> 21 | G5: 21 | H5: =IF(F5=G5,"OK","MISMATCH") -> OK
A6: Master toilet | B6: =COUNTIFS(Items!$B:$B,$A6,Items!$C:$C,"Furniture") -> 7 | C6: =COUNTIFS(Items!$B:$B,$A6,Items!$C:$C,"Décor") -> 6 | D6: =COUNTIFS(Items!$B:$B,$A6,Items!$C:$C,"Finish") -> 4 | E6: =COUNTIFS(Items!$B:$B,$A6,Items!$C:$C,"Lighting / textile") -> 7 | F6: =SUM(B6:E6) -> 24 | G6: 24 | H6: =IF(F6=G6,"OK","MISMATCH") -> OK
A7: Bedroom-1 | B7: =COUNTIFS(Items!$B:$B,$A7,Items!$C:$C,"Furniture") -> 8 | C7: =COUNTIFS(Items!$B:$B,$A7,Items!$C:$C,"Décor") -> 5 | D7: =COUNTIFS(Items!$B:$B,$A7,Items!$C:$C,"Finish") -> 4 | E7: =COUNTIFS(Items!$B:$B,$A7,Items!$C:$C,"Lighting / textile") -> 7 | F7: =SUM(B7:E7) -> 24 | G7: 24 | H7: =IF(F7=G7,"OK","MISMATCH") -> OK
A8: Bedroom-1 walk-in wardrobe | B8: =COUNTIFS(Items!$B:$B,$A8,Items!$C:$C,"Furniture") -> 5 | C8: =COUNTIFS(Items!$B:$B,$A8,Items!$C:$C,"Décor") -> 3 | D8: =COUNTIFS(Items!$B:$B,$A8,Items!$C:$C,"Finish") -> 3 | E8: =COUNTIFS(Items!$B:$B,$A8,Items!$C:$C,"Lighting / textile") -> 3 | F8: =SUM(B8:E8) -> 14 | G8: 14 | H8: =IF(F8=G8,"OK","MISMATCH") -> OK
A9: Bedroom-1 toilet | B9: =COUNTIFS(Items!$B:$B,$A9,Items!$C:$C,"Furniture") -> 5 | C9: =COUNTIFS(Items!$B:$B,$A9,Items!$C:$C,"Décor") -> 3 | D9: =COUNTIFS(Items!$B:$B,$A9,Items!$C:$C,"Finish") -> 4 | E9: =COUNTIFS(Items!$B:$B,$A9,Items!$C:$C,"Lighting / textile") -> 5 | F9: =SUM(B9:E9) -> 17 | G9: 17 | H9: =IF(F9=G9,"OK","MISMATCH") -> OK
A10: Bedroom-2 (+ vestibule) | B10: =COUNTIFS(Items!$B:$B,$A10,Items!$C:$C,"Furniture") -> 7 | C10: =COUNTIFS(Items!$B:$B,$A10,Items!$C:$C,"Décor") -> 4 | D10: =COUNTIFS(Items!$B:$B,$A10,Items!$C:$C,"Finish") -> 5 | E10: =COUNTIFS(Items!$B:$B,$A10,Items!$C:$C,"Lighting / textile") -> 6 | F10: =SUM(B10:E10) -> 22 | G10: 22 | H10: =IF(F10=G10,"OK","MISMATCH") -> OK
A11: Bedroom-2 toilet | B11: =COUNTIFS(Items!$B:$B,$A11,Items!$C:$C,"Furniture") -> 6 | C11: =COUNTIFS(Items!$B:$B,$A11,Items!$C:$C,"Décor") -> 6 | D11: =COUNTIFS(Items!$B:$B,$A11,Items!$C:$C,"Finish") -> 4 | E11: =COUNTIFS(Items!$B:$B,$A11,Items!$C:$C,"Lighting / textile") -> 5 | F11: =SUM(B11:E11) -> 21 | G11: 21 | H11: =IF(F11=G11,"OK","MISMATCH") -> OK
A12: Large balcony | B12: =COUNTIFS(Items!$B:$B,$A12,Items!$C:$C,"Furniture") -> 7 | C12: =COUNTIFS(Items!$B:$B,$A12,Items!$C:$C,"Décor") -> 5 | D12: =COUNTIFS(Items!$B:$B,$A12,Items!$C:$C,"Finish") -> 4 | E12: =COUNTIFS(Items!$B:$B,$A12,Items!$C:$C,"Lighting / textile") -> 6 | F12: =SUM(B12:E12) -> 22 | G12: 22 | H12: =IF(F12=G12,"OK","MISMATCH") -> OK
A13: Small balcony | B13: =COUNTIFS(Items!$B:$B,$A13,Items!$C:$C,"Furniture") -> 4 | C13: =COUNTIFS(Items!$B:$B,$A13,Items!$C:$C,"Décor") -> 3 | D13: =COUNTIFS(Items!$B:$B,$A13,Items!$C:$C,"Finish") -> 3 | E13: =COUNTIFS(Items!$B:$B,$A13,Items!$C:$C,"Lighting / textile") -> 3 | F13: =SUM(B13:E13) -> 13 | G13: 13 | H13: =IF(F13=G13,"OK","MISMATCH") -> OK
... A15: Lift lobby (in upper lounge) | B15: =COUNTIFS(Items!$B:$B,$A15,Items!$C:$C,"Furniture") -> 1 | C15: =COUNTIFS(Items!$B:$B,$A15,Items!$C:$C,"Décor") -> 3 | D15: =COUNTIFS(Items!$B:$B,$A15,Items!$C:$C,"Finish") -> 2 | E15: =COUNTIFS(Items!$B:$B,$A15,Items!$C:$C,"Lighting / textile") -> 2 | F15: =SUM(B15:E15) -> 8 | G15: 8 | H15: =IF(F15=G15,"OK","MISMATCH") -> OK
A16: TOTAL | B16: =SUM(B2:B15) -> 76 | C16: =SUM(C2:C15) -> 62 | D16: =SUM(D2:D15) -> 53 | E16: =SUM(E2:E15) -> 68 | F16: =SUM(F2:F15) -> 259 | G16: =SUM(G2:G15) -> 259 | H16: =IF(F16=G16,"OK","MISMATCH") -> OK
A18: Instances to place (Placements sheet) | B18: =COUNTA(Placements!A:A)-1 -> 291
A19: Unique mesh assets to build | B19: 181 | C19: (distinct Mesh_Asset values — identical items share one mesh)
A21: "Rev 3 table items" = item count per space in RMD_FF_Unified_Furnishing_Table_rev3_Luxury.pdf (source of truth).

Sheet Items
A1: Item_Code | B1: Space | C1: Category | D1: Item (rev 3 wording) | E1: Family | F1: Generator | G1: Host | H1: Qty | I1: L_mm | J1: W_mm | K1: H_mm | L1: Pos_X_mm | M1: Pos_Y_mm | N1: Pos_Z_mm | O1: Rot_Z_deg | P1: Faces | Q1: Params_JSON | R1: Material_Slots | S1: Detailed_Description | T1: Mesh_Asset | U1: UE_Name | V1: Nanite | W1: LOD_Target | X1: Fit_Note
A2: UL-01 | B2: Upper lounge | C2: Furniture | D2: Pair of bouclé swivel barrel chairs | E2: CHAIR_BARREL_SWIVEL | F2: gen_chair_barrel | G2: floor | H2: 2 | I2: 820 | J2: 820 | K2: 760 | L2: 7550 | M2: 5750 | N2: 0 | O2: 90 | P2: W | Q2: {"seat_h": 420, "back_h": 760, "shell_t": 90, "base": "swivel disc Ø450", "channels": 0} | R2: M_Boucle_Grey | S2: Pair of bouclé swivel barrel chairs. Build: Lathe-swept barrel shell (260° wrap) solidified 90 mm, loose seat cushion, concealed swivel disc base; subdivision level 2. Size: Ø820 × H 760 mm; 2 instance(s); floor-standing. Materials: M_Boucle_Grey. | T2: SM_FF_CHAIR_BARREL_SWIVEL_820x820x760 | U2: SM_FF_UL_01 | V2: Yes | W2: 20–60k tris (hero)
A3: UL-02 | B3: Upper lounge | C3: Furniture | D3: Round travertine coffee table Ø700 | E3: TABLE_ROUND | F3: gen_table_round | G3: floor | H3: 1 | I3: 700 | J3: 700 | K3: 400 | L3: 6750 | M3: 6300 | N3: 0 | O3: 0 | P3: — | Q3: {"top_t": 40, "base": "travertine drum", "edge": "eased 6"} | R3: M_Travertine | S3: Round travertine coffee table Ø700. Build: Round top with eased edge on a drum or pedestal base; stone/travertine material with honed finish. Size: Ø700 × H 400 mm; 1 instance(s); floor-standing. Materials: M_Travertine. | T3: SM_FF_TABLE_ROUND_700x700x400 | U3: SM_FF_UL_02 | V3: Yes | W3: 20–60k tris (hero)
A4: UL-03 | B4: Upper lounge | C4: Furniture | D4: Walnut console 1500×350 with solid-brass inlay | E4: CONSOLE | F4: gen_console | G4: floor | H4: 1 | I4: 1500 | J4: 350 | K4: 800 | L4: 8470 | M4: 8102 | N4: 0 | O4: 0 | P4: — | Q4: {"top_t": 40, "leg": "panel", "inlay": "solid brass", "drawer_count": 0} | R4: M_Walnut, M_Brass_Brushed | S4: Walnut console 1500×350 with solid-brass inlay. Build: Wall console: top slab + side panels or brass legs; optional solid-brass inlay strip routed 6 mm into the top; 20 mm wall stand-off. Size: 1500 × 350 × H 800 mm; 1 instance(s); floor-standing. Materials: M_Walnut, M_Brass_Brushed. | T4: SM_FF_CONSOLE_1500x350x800 | U4: SM_FF_UL_03 | V4: Yes | W4: 20–60k tris (hero)
A5: UL-04 | B5: Upper lounge | C5: Furniture | D5: Low walnut bookshelf 1800×350 with bronze-framed glass ends | E5: BOOKSHELF_LOW | F5: gen_bookshelf | G5: floor | H5: 1 | I5: 1400 | J5: 350 | K5: 900 | L5: 8540 | M5: 4734 | N5: 0 | O5: 0 | P5: — | Q5: {"shelves": 2, "bay_w": 480, "end_panels": "bronze-framed glass", "plinth": 60} | R5: M_Walnut, M_Bronze_Dark, M_Glass_LowIron | S5: Low walnut bookshelf 1800×350 with bronze-framed glass ends. Build: Low walnut shelving: carcass 25 mm, adjustable shelves, bronze-framed glass end panels, recessed plinth. Size: 1400 × 350 × H 900 mm; 1 instance(s); floor-standing. Materials: M_Walnut, M_Bronze_Dark, M_Glass_LowIron. Fit note: fitted at 1450 — full length of the solid wall. | T5: SM_FF_BOOKSHELF_LOW_1400x350x900 | U5: SM_FF_UL_04 | V5: No | W5: 20–60k tris (hero) | X5: fitted at 1450 — full length of the solid wall
A6: UL-05 | B6: Upper lounge | C6: Furniture | D6: Cream velvet loveseat 1600×850 | E6: SOFA_LOVESEAT | F6: gen_sofa | G6: floor | H6: 1 | I6: 1600 | J6: 850 | K6: 780 | L6: 5575 | M6: 6300 | N6: 0 | O6: 270 | P6: E | Q6: {"seat_h": 440, "seat_cushions": 2, "back_cushions": 2, "arm_w": 180, "plinth_inset": 60, "piping": true, "crown": 22, "back_tilt_deg": 12, "gap": 4} | R6: M_Velvet_Cream | S6: Cream velvet loveseat 1600×850. Build: Same build as the GF sectional: recessed dark-bronze plinth, upholstered deck, frame with rolled top, crowned piped seat cushions, loose back cushions tilted 12°, 4 mm slot gaps, modifiers baked. Size: 1600 × 850 × H 780 mm; 1 instance(s); floor-standing. Materials: M_Velvet_Cream. Fit note: faces the void (keeps the vestibule door clear). | T6: SM_FF_SOFA_LOVESEAT_1600x850x780 | U6: SM_FF_UL_05 | V6: Yes | W6: 20–60k tris (hero) | X6: faces the void (keeps the vestibule door clear)
A7: UL-06 | B7: Upper lounge | C7: Furniture | D7: Walnut drum side tables ×2 Ø450 with marble tops | E7: TABLE_DRUM | F7: gen_table_drum | G7: floor | H7: 2 | I7: 450 | J7: 450 | K7: 500 | L7: 5575 | M7: 5230 | N7: 0 | O7: 0 | P7: — | Q7: {"top_t": 20, "body": "walnut drum", "top_inset": 0} | R7: M_Walnut, M_Marble_Calacatta | S7: Walnut drum side tables ×2 Ø450 with marble tops. Build: Cylindrical walnut drum body (vertical grain), marble top slab 20 mm with 2 mm bevel. Size: Ø450 × H 500 mm; 2 instance(s); floor-standing. Materials: M_Walnut, M_Marble_Calacatta. | T7: SM_FF_TABLE_DRUM_450x450x500 | U7: SM_FF_UL_06 | V7: Yes | W7: 20–60k tris (hero)
A8: UL-07 | B8: Upper lounge | C8: Furniture | D8: Pair of bouclé poufs Ø450 | E8: POUF_ROUND | F8: gen_pouf | G8: floor | H8: 2 | I8: 450 | J8: 450 | K8: 420 | L8: 8150 | M8: 7680 | N8: 0 | O8: 0 | P8: — | Q8: {"bevel": 60, "fabric": "boucle"} | R8: M_Boucle_Grey | S8: Pair of bouclé poufs Ø450. Build: Cylindrical pouf with large bevel (60) and subdivision, bouclé normal detail. Size: Ø450 × H 420 mm; 2 instance(s); floor-standing. Materials: M_Boucle_Grey. Fit note: tucked at the console. | T8: SM_FF_POUF_ROUND_450x450x420 | U8: SM_FF_UL_07 | V8: Yes | W8: 20–60k tris (hero) | X8: tucked at the console
A9: UL-08 | B9: Upper lounge | C9: Furniture | D9: Olive tree 1.8 m in a hand-finished stone planter | E9: PLANTER_TREE | F9: gen_planter_tree | G9: floor | H9: 1 | I9: 600 | J9: 600 | K9: 1800 | L9: 8900 | M9: 5600 | N9: 0 | O9: 0 | P9: — | Q9: {"pot_h": 600, "species": "olive", "crown_density": "high", "trim_to_room": true} | R9: M_Travertine, M_Foliage_Olive | S9: Olive tree 1.8 m in a hand-finished stone planter. Build: Stone planter (tapered cylinder) + branch generator (depth 4–5) with olive leaf cards; geometry trimmed 15 mm off walls / 2.70 m ceiling (same as GF QC). Size: Ø600 × H 1800 mm; 1 instance(s); floor-standing. Materials: M_Travertine, M_Foliage_Olive. | T9: SM_FF_PLANTER_TREE_600x600x1800 | U9: SM_FF_UL_08 | V9: No | W9: 20–60k tris (hero)
A10: UL-09 | B10: Upper lounge | C10: Décor | D10: Abstract art above the console | E10: ART_FRAME | F10: gen_art | G10: wall | H10: 1 | I10: 1100 | J10: 40 | K10: 800 | L10: 8470 | M10: 8258 | N10: 1100 | O10: 180 | P10: S | Q10: {"frame_w": 30, "frame_d": 40, "canvas_inset": 5, "image": "natural abstract", "centre_h": 1500} | S10: Abstract art above the console. Build: Framed artwork: walnut frame, canvas plane with image texture slot; wall stand-off 2 mm. Size: 1100 × 40 × H 800 mm; 1 instance(s); wall-mounted, faces S. Materials: per family default. | T10: SM_FF_ART_FRAME_1100x40x800 | U10: SM_FF_UL_09 | V10: Yes | W10: 1–8k tris
A11: UL-10 | B11: Upper lounge | C11: Décor | D11: Sculptural vase | E11: ACCESSORY | F11: gen_accessory | G11: host | H11: 1 | I11: 250 | J11: 250 | K11: 150 | L11: 8000 | M11: 8100 | N11: auto (drop onto host) | O11: 0 | P11: — | Q11: {"type": "vase", "scatter_on": "host top"} | R11: M_Ceramic_Matte | S11: Sculptural vase. Build: Small décor generated from the accessory kit (vase, tray, books, bowl, candles, diffuser, towels…) and dropped onto the host surface at the marked point. Size: 250 × 250 × H 150 mm; 1 instance(s); placed on its host surface. Materials: M_Ceramic_Matte. | T11: SM_FF_ACCESSORY_250x250x150 | U11: SM_FF_UL_10 | V11: Yes | W11: 1–8k tris
A12: UL-11 | B12: Upper lounge | C12: Décor | D12: Coffee-table books | E12: ACCESSORY | F12: gen_accessory | G12: host | H12: 1 | I12: 250 | J12: 250 | K12: 150 | L12: 6600 | M12: 6150 | N12: auto (drop onto host) | O12: 0 | P12: — | Q12: {"type": "books", "scatter_on": "host top"} | S12: Coffee-table books. Build: Small décor generated from the accessory kit (vase, tray, books, bowl, candles, diffuser, towels…) and dropped onto the host surface at the marked point. Size: 250 × 250 × H 150 mm; 1 instance(s); placed on its host surface. Materials: per family default. | T12: SM_FF_ACCESSORY_250x250x150 | U12: SM_FF_UL_11 | V12: Yes | W12: 1–8k tris
A13: UL-12 | B13: Upper lounge | C13: Décor | D13: Gallery wall of 4 limited-edition prints in walnut frames | E13: ART_FRAME | F13: gen_art | G13: wall | H13: 4 | I13: 1280 | J13: 40 | K13: 900 | L13: 8540 | M13: 4580 | N13: 1050 | O13: 0 | P13: N | Q13: {"frame_w": 30, "frame_d": 40, "canvas_inset": 5, "image": "natural abstract", "centre_h": 1500} | R13: M_Walnut | S13: Gallery wall of 4 limited-edition prints in walnut frames. Build: Framed artwork: walnut frame, canvas plane with image texture slot; wall stand-off 2 mm. Size: 1280 × 40 × H 900 mm; 4 instance(s); wall-mounted, faces N. Materials: M_Walnut. | T13: SM_FF_ART_FRAME_1280x40x900 | U13: SM_FF_UL_12 | V13: Yes | W13: 1–8k tris
A14: UL-13 | B14: Upper lounge | C14: Décor | D14: Curated ceramics on the shelves | E14: ACCESSORY | F14: gen_accessory | G14: host | H14: 1 | I14: 250 | J14: 250 | K14: 150 | L14: 8540 | M14: 4734 | N14: auto (drop onto host) | O14: 0 | P14: — | Q14: {"type": "ceramics", "scatter_on": "host top"} | R14: M_Ceramic_Matte | S14: Curated ceramics on the shelves. Build: Small décor generated from the accessory kit (vase, tray, books, bowl, candles, diffuser, towels…) and dropped onto the host surface at the marked point. Size: 250 × 250 × H 150 mm; 1 instance(s); placed on its host surface. Materials: M_Ceramic_Matte. | T14: SM_FF_ACCESSORY_250x250x150 | U14: SM_FF_UL_13 | V14: Yes | W14: 1–8k tris
A15: UL-14 | B15: Upper lounge | C15: Décor | D15: Brass tray with candles | E15: ACCESSORY | F15: gen_accessory | G15: host | H15: 1 | I15: 250 | J15: 250 | K15: 150 | L15: 6900 | M15: 6420 | N15: auto (drop onto host) | O15: 0 | P15: — | Q15: {"type": "tray + candles", "scatter_on": "host top"} | R15: M_Brass_Brushed | S15: Brass tray with candles. Build: Small décor generated from the accessory kit (vase, tray, books, bowl, candles, diffuser, towels…) and dropped onto the host surface at the marked point. Size: 250 × 250 × H 150 mm; 1 instance(s); placed on its host surface. Materials: M_Brass_Brushed. | T15: SM_FF_ACCESSORY_250x250x150 | U15: SM_FF_UL_14 | V15: Yes | W15: 1–8k tris
A16: UL-15 | B16: Upper lounge | C16: Décor | D16: Travertine bowl | E16: ACCESSORY | F16: gen_accessory | G16: host | H16: 1 | I16: 250 | J16: 250 | K16: 150 | L16: 9050 | M16: 8100 | N16: auto (drop onto host) | O16: 0 | P16: — | Q16: {"type": "bowl", "scatter_on": "host top"} | R16: M_Travertine | S16: Travertine bowl. Build: Small décor generated from the accessory kit (vase, tray, books, bowl, candles, diffuser, towels…) and dropped onto the host surface at the marked point. Size: 250 × 250 × H 150 mm; 1 instance(s); placed on its host surface. Materials: M_Travertine. | T16: SM_FF_ACCESSORY_250x250x150 | U16: SM_FF_UL_15 | V16: Yes | W16: 1–8k tris
A17: UL-16 | B17: Upper lounge | C17: Finish | D17: White ogee panels | E17: WALL_PANEL_OGEE | F17: gen_ogee_panels | G17: wall | H17: 1 | I17: 5049 | J17: 3718 | K17: 2550 | L17: 6762 | M17: 6418 | N17: 0 | O17: 0 | P17: — | Q17: {"profile": "40×20 ogee", "dado_h": 880, "skirting_h": 120, "cornice_h": 150, "panel_w": "auto 600–900"} | R17: M_Paint_WarmWhite | S17: White ogee panels. Build: Ogee picture-frame moulding system (same profile as GF dining) laid out per wall face with skirting, dado and cornice. Size: room 5049 × 3718 × H 2550 mm; 1 instance(s); wall-mounted, faces —. Materials: M_Paint_WarmWhite. | T17: SM_FF_UL_WALL_PANEL_OGEE | U17: SM_FF_UL_16 | V17: Yes | W17: procedural / per-room
A18: UL-17 | B18: Upper lounge | C18: Finish | D18: Honed Italian light-stone floor | E18: FINISH_FLOOR | F18: gen_floor_finish | G18: room | H18: 1 | I18: 5049 | J18: 3718 | K18: 15 | L18: 6762 | M18: 6418 | N18: 0 | O18: 0 | P18: — | Q18: {"pattern": "honed stone 1200×600", "grout": 2} | R18: M_Stone_LightHoned, M_Travertine | S18: Honed Italian light-stone floor. Build: Room-polygon floor finish (herringbone / large-format stone / deck boards) with pattern-aware UVs. Size: room 5049 × 3718 × H 15 mm; 1 instance(s); applied to the whole room. Materials: M_Stone_LightHoned, M_Travertine. | T18: SM_FF_UL_FINISH_FLOOR | U18: SM_FF_UL_17 | V18: Yes | W18: procedural / per-room
A19: UL-18 | B19: Upper lounge | C19: Finish | D19: Glass balustrade with dark-bronze cap | E19: BALUSTRADE_GLASS | F19: gen_balustrade | G19: floor | H19: 1 | I19: 3718 | J19: 35 | K19: 1100 | L19: 9282 | M19: 6418 | N19: 0 | O19: 90 | P19: W | Q19: {"glass": "low-iron 13.5 laminated", "cap": "dark bronze", "clamp": "bronze"} | R19: M_Bronze_Dark, M_Glass_LowIron | S19: Glass balustrade with dark-bronze cap. Build: Frameless glass balustrade with bronze cap rail/handrail and clamps. Size: 3718 × 35 × H 1100 mm; 1 instance(s); floor-standing. Materials: M_Bronze_Dark, M_Glass_LowIron. | T19: SM_FF_BALUSTRADE_GLASS_3720x40x1100 | U19: SM_FF_UL_18 | V19: No | W19: procedural / per-room
A20: UL-19 | B20: Upper lounge | C20: Finish | D20: Walnut slatted feature panel | E20: WALL_FEATURE_PANEL | F20: gen_feature_panel | G20: wall | H20: 1 | I20: 1637 | J20: 27 | K20: 2700 | L20: 8468 | M20: 8264 | N20: 0 | O20: 180 | P20: S | Q20: {"type": "walnut slats", "module": 60, "depth": 40} | R20: M_Walnut | S20: Walnut slatted feature panel. Build: Feature wall panel: walnut slats (module 60 / gap 15), fluted walnut, upholstered fabric panels or marble slabs with bronze trims. Size: 1637 × 27 × H 2700 mm; 1 instance(s); wall-mounted, faces S. Materials: M_Walnut. | T20: SM_FF_WALL_FEATURE_PANEL_1640x30x2700 | U20: SM_FF_UL_19 | V20: Yes | W20: procedural / per-room
A21: UL-20 | B21: Upper lounge | C21: Finish | D21: Tray ceiling with stepped cornice | E21: CEILING_TRAY | F21: gen_ceiling_tray | G21: ceiling | H21: 1 | I21: 3200 | J21: 2350 | K21: 200 | L21: 6700 | M21: 6325 | N21: 2950 | O21: 0 | P21: — | Q21: {"inset": 400, "steps": 2, "cove_led": true, "ceiling_h": 2750, "tray_h": 2950} | R21: M_Paint_WarmWhite | S21: Tray ceiling with stepped cornice. Build: Stepped tray ceiling with cornice and concealed LED cove (2700 K). Size: 3200 × 2350 × H 200 mm; 1 instance(s); ceiling-hung / recessed. Materials: M_Paint_WarmWhite. | T21: SM_FF_UL_CEILING_TRAY | U21: SM_FF_UL_20 | V21: Yes | W21: procedural / per-room
A22: UL-21 | B22: Upper lounge | C22: Finish | D22: Brass inlay strip at the void edge | E22: INLAY_STRIP | F22: gen_inlay | G22: floor | H22: 1 | I22: 3718 | J22: 32 | K22: 5 | L22: 9246 | M22: 6418 | N22: 0 | O22: 90 | P22: W | Q22: {"width": 20, "material": "brass"} | R22: M_Brass_Brushed | S22: Brass inlay strip at the void edge. Build: Metal/stone strip inlaid flush in the floor or nosing at an edge. Size: 3718 × 32 × H 5 mm; 1 instance(s); floor-standing. Materials: M_Brass_Brushed. | T22: SM_FF_INLAY_STRIP_3720x30x5 | U22: SM_FF_UL_21 | V22: Yes | W22: procedural / per-room
A23: UL-22 | B23: Upper lounge | C23: Lighting / textile | D23: Sculptural brass chandelier Ø900 with concealed LED cove (dimmable scenes) | E23: LIGHT_CHANDELIER | F23: gen_chandelier | G23: ceiling | H23: 1 | I23: 900 | J23: 900 | K23: 600 | L23: 6750 | M23: 6300 | N23: 2750 | O23: 0 | P23: — | Q23: {"style": "sculptural brass Ø900", "drop_to_bottom_mm": 2200, "lumens": 3000} | R23: M_Brass_Brushed | S23: Sculptural brass chandelier Ø900 with concealed LED cove (dimmable scenes). Build: Ceiling-hung fixture with canopy, rod/cables and emissive parts + UE point/spot lights. Size: Ø900 × H 600 mm; 1 instance(s); ceiling-hung / recessed. Materials: M_Brass_Brushed. | T23: SM_FF_LIGHT_CHANDELIER_900x900x600 | U23: SM_FF_UL_22 | V23: Yes | W23: 2–15k tris
A24: UL-23 | B24: Upper lounge | C24: Lighting / textile | D24: Brass floor reading lamp | E24: LIGHT_FLOOR_LAMP | F24: gen_floor_lamp | G24: floor | H24: 1 | I24: 350 | J24: 350 | K24: 1500 | L24: 5450 | M24: 7700 | N24: 0 | O24: 0 | P24: — | Q24: {"style": "brass reading"} | R24: M_Brass_Brushed | S24: Brass floor reading lamp. Build: Brass floor lamp: weighted base, stem, conical shade. Size: Ø350 × H 1500 mm; 1 instance(s); floor-standing. Materials: M_Brass_Brushed. | T24: SM_FF_LIGHT_FLOOR_LAMP_350x350x1500 | U24: SM_FF_UL_23 | V24: Yes | W24: 2–15k tris
A25: UL-24 | B25: Upper lounge | C25: Lighting / textile | D25: Disc sconces ×2 | E25: LIGHT_SCONCE | F25: gen_sconce | G25: wall | H25: 2 | I25: 200 | J25: 200 | K25: 200 | L25: 7690 | M25: 8170 | N25: 1500 | O25: 0 | P25: — | Q25: {"style": "disc", "centre_h": 1600} | S25: Disc sconces ×2. Build: Wall sconce with back plate, emissive diffuser + UE light. Size: Ø200 × H 200 mm; 2 instance(s); wall-mounted, faces —. Materials: per family default. | T25: SM_FF_LIGHT_SCONCE_200x200x200 | U25: SM_FF_UL_24 | V25: Yes | W25: 2–15k tris
A26: UL-25 | B26: Upper lounge | C26: Lighting / textile | D26: Picture light | E26: LIGHT_SPOT | F26: gen_spot | G26: ceiling | H26: 1 | I26: 700 | J26: 40 | K26: 80 | L26: 8550 | M26: 4620 | N26: 2750 | O26: 0 | P26: N | Q26: {"beam_deg": 40, "type": "picture light"} | R26: M_Brass_Brushed | S26: Picture light. Build: Recessed downlight / uplight / picture light / niche light. Size: 700 × 40 × H 80 mm; 1 instance(s); ceiling-hung / recessed. Materials: M_Brass_Brushed. | T26: SM_FF_LIGHT_SPOT_700x40x80 | U26: SM_FF_UL_25 | V26: Yes | W26: 2–15k tris
A27: UL-26 | B27: Upper lounge | C27: Lighting / textile | D27: Hand-knotted wool-silk rug 2400×1700 | E27: RUG | F27: gen_rug | G27: floor | H27: 1 | I27: 2400 | J27: 1700 | K27: 12 | L27: 6750 | M27: 6300 | N27: 0 | O27: 0 | P27: — | Q27: {"pile": "low", "edge_bevel": 5, "pattern": "hand-knotted wool-silk"} | R27: M_Wool_Rug | S27: Hand-knotted wool-silk rug 2400×1700. Build: Rug slab with bevelled edge; shag variant uses displaced grid; hand-knotted pattern texture slot. Size: 2400 × 1700 × H 12 mm; 1 instance(s); floor-standing. Materials: M_Wool_Rug. | T27: SM_FF_RUG_2400x1700x12 | U27: SM_FF_UL_26 | V27: Yes | W27: 2–15k tris
A28: UL-27 | B28: Upper lounge | C28: Lighting / textile | D28: Velvet cushions in charcoal and pale grey | E28: SOFT_SET | F28: gen_soft_set | G28: host | H28: 1 | I28: 250 | J28: 250 | K28: 150 | L28: 5400 | M28: 6200 | N28: auto (drop onto host) | O28: 0 | P28: — | Q28: {"items": "cushion"} | R28: M_Velvet_Cream, M_Velvet_Charcoal | S28: Velvet cushions in charcoal and pale grey. Build: Cushions / throws / bed runner / towels / bath mat generated from the soft-furnishing kit onto the host. Size: 250 × 250 × H 150 mm; 1 instance(s); placed on its host surface. Materials: M_Velvet_Cream, M_Velvet_Charcoal. | T28: SM_FF_SOFT_SET_250x250x150 | U28: SM_FF_UL_27 | V28: Yes | W28: 2–15k tris
A29: UL-28 | B29: Upper lounge | C29: Lighting / textile | D29: Bouclé throw | E29: SOFT_SET | F29: gen_soft_set | G29: host | H29: 1 | I29: 250 | J29: 250 | K29: 150 | L29: 5400 | M29: 6900 | N29: auto (drop onto host) | O29: 0 | P29: — | Q29: {"items": "throw"} | R29: M_Boucle_Grey | S29: Bouclé throw. Build: Cushions / throws / bed runner / towels / bath mat generated from the soft-furnishing kit onto the host. Size: 250 × 250 × H 150 mm; 1 instance(s); placed on its host surface. Materials: M_Boucle_Grey. | T29: SM_FF_SOFT_SET_250x250x150 | U29: SM_FF_UL_28 | V29: Yes | W29: 2–15k tris
A30: VO-01 | B30: Void over GF lounge | C30: Furniture | D30: Low honed-stone planter trough 1500×250 at the balustrade corner | E30: PLANTER_TROUGH | F30: gen_trough | G30: floor | H30: 1 | I30: 1500 | J30: 250 | K30: 400 | L30: 9162 | M30: 7050 | N30: 0 | O30: 90 | P30: — | Q30: {"wall_t": 30, "plants": "trailing"} | R30: M_Travertine, M_Foliage_Olive | S30: Low honed-stone planter trough 1500×250 at the balustrade corner. Build: Honed stone trough (hollow, 30 mm walls) planted with trailing foliage cards. Size: 1500 × 250 × H 400 mm; 1 instance(s); floor-standing. Materials: M_Travertine, M_Foliage_Olive. Fit note: on the lounge side of the balustrade (the void has no floor). | T30: SM_FF_PLANTER_TROUGH_1500x250x400 | U30: SM_FF_VO_01 | V30: No | W30: 20–60k tris (hero) | X30: on the lounge side of the balustrade (the void has no floor)
A31: VO-02 | B31: Void over GF lounge | C31: Décor | D31: Overlooks the crystal ring cluster below | E31: ACCESSORY | F31: gen_accessory | G31: host | H31: 1 | I31: 1200 | J31: 1200 | K31: 150 | L31: 11350 | M31: 6400 | N31: auto (drop onto host) | O31: 0 | P31: — | Q31: {"type": "sightline marker (no geometry)", "scatter_on": "host top"} | S31: Overlooks the crystal ring cluster below. Build: Small décor generated from the accessory kit (vase, tray, books, bowl, candles, diffuser, towels…) and dropped onto the host surface at the marked point. Size: Ø1200 × H 150 mm; 1 instance(s); placed on its host surface. Materials: per family default. | T31: SM_FF_ACCESSORY_1200x1200x150 | U31: SM_FF_VO_02 | V31: No | W31: 1–8k tris
A32: VO-03 | B32: Void over GF lounge | C32: Décor | D32: Trailing plants spilling over the trough | E32: PLANT_SMALL | F32: gen_plant_small | G32: floor | H32: 1 | I32: 300 | J32: 300 | K32: 600 | L32: 9162 | M32: 7050 | N32: 0 | O32: 0 | P32: — | Q32: {"pot_d": 300, "species": "trailing"} | R32: M_Foliage_Olive | S32: Trailing plants spilling over the trough. Build: Potted plant from leaf-card kit. Size: Ø300 × H 600 mm; 1 instance(s); floor-standing. Materials: M_Foliage_Olive. | T32: SM_FF_PLANT_SMALL_300x300x600 | U32: SM_FF_VO_03 | V32: No | W32: 1–8k tris
A33: VO-04 | B33: Void over GF lounge | C33: Finish | D33: Low-iron glass balustrade with bronze handrail and clamps | E33: BALUSTRADE_GLASS | F33: gen_balustrade | G33: floor | H33: 1 | I33: 3718 | J33: 40 | K33: 1100 | L33: 9290 | M33: 6418 | N33: 0 | O33: 270 | P33: E | Q33: {"glass": "low-iron 13.5 laminated", "cap": "dark bronze", "clamp": "bronze"} | R33: M_Bronze_Dark, M_Glass_LowIron | S33: Low-iron glass balustrade with bronze handrail and clamps. Build: Frameless glass balustrade with bronze cap rail/handrail and clamps. Size: 3718 × 40 × H 1100 mm; 1 instance(s); floor-standing. Materials: M_Bronze_Dark, M_Glass_LowIron. | T33: SM_FF_BALUSTRADE_GLASS_3720x40x1100 | U33: SM_FF_VO_04 | V33: No | W33: procedural / per-room
A34: VO-05 | B34: Void over GF lounge | C34: Finish | D34: Stone nosing at the void edge | E34: INLAY_STRIP | F34: gen_inlay | G34: floor | H34: 1 | I34: 400 | J34: 37 | K34: 5 | L34: 9244 | M34: 5100 | N34: 0 | O34: 270 | P34: E | Q34: {"width": 20, "material": "stone nosing"} | R34: M_Travertine | S34: Stone nosing at the void edge. Build: Metal/stone strip inlaid flush in the floor or nosing at an edge. Size: 400 × 37 × H 5 mm; 1 instance(s); floor-standing. Materials: M_Travertine. | T34: SM_FF_INLAY_STRIP_400x40x5 | U34: SM_FF_VO_05 | V34: Yes | W34: procedural / per-room
A35: VO-06 | B35: Void over GF lounge | C35: Lighting / textile | D35: Full-height motorised silk-linen sheers on the courtyard side | E35: CURTAIN | F35: gen_curtain | G35: wall | H35: 1 | I35: 3640 | J35: 45 | K35: 6100 | L35: 12982 | M35: 6420 | N35: 0 | O35: 90 | P35: W | Q35: {"fullness": 2.2, "fold_pitch": 160, "track": "motorised ceiling", "layers": "sheer, full height"} | R35: M_Fabric_Linen | S35: Full-height motorised silk-linen sheers on the courtyard side. Build: Curtain surface swept along the track with sine folds; sheer = translucent two-sided material. Size: 3640 × 45 × H 6100 mm; 1 instance(s); wall-mounted, faces W. Materials: M_Fabric_Linen. | T35: SM_FF_CURTAIN_3640x40x6100 | U35: SM_FF_VO_06 | V35: No | W35: 2–15k tris
A36: VO-07 | B36: Void over GF lounge | C36: Lighting / textile | D36: Concealed LED under the handrail | E36: LIGHT_LED_STRIP | F36: gen_led_strip | G36: host | H36: 1 | I36: 3640 | J36: 40 | K36: 10 | L36: 9290 | M36: 6420 | N36: auto (drop onto host) | O36: 0 | P36: — | Q36: {"cct": 2700} | S36: Concealed LED under the handrail. Build: Concealed LED strip along the given line (rect light, emissive strip). Size: 3640 × 40 × H 10 mm; 1 instance(s); placed on its host surface. Materials: per family default. | T36: SM_FF_LIGHT_LED_STRIP_3640x40x10 | U36: SM_FF_VO_07 | V36: Yes | W36: 2–15k tris
A37: VO-08 | B37: Void over GF lounge | C37: Lighting / textile | D37: Uplight washing the void wall | E37: LIGHT_SPOT | F37: gen_spot | G37: ceiling | H37: 1 | I37: 250 | J37: 250 | K37: 80 | L37: 12800 | M37: 6400 | N37: 2750 | O37: 0 | P37: — | Q37: {"beam_deg": 40, "type": "uplight"} | R37: M_Brass_Brushed | S37: Uplight washing the void wall. Build: Recessed downlight / uplight / picture light / niche light. Size: Ø250 × H 80 mm; 1 instance(s); ceiling-hung / recessed. Materials: M_Brass_Brushed. | T37: SM_FF_LIGHT_SPOT_250x250x80 | U37: SM_FF_VO_08 | V37: Yes | W37: 2–15k tris
A38: MB-01 | B38: Master bedroom | C38: Furniture | D38: King bed 1829×1981 with full-height upholstered headboard wall | E38: BED_PLATFORM | F38: gen_bed | G38: floor | H38: 1 | I38: 1980 | J38: 1829 | K38: 450 | L38: 2950 | M38: 5784 | N38: 0 | O38: 90 | P38: W | Q38: {"mattress_h": 250, "base_h": 200, "base_inset": 60, "leg": "recessed plinth 60", "bevel": 15, "duvet_drape": 120} | R38: M_Velvet_Cream | S38: King bed 1829×1981 with full-height upholstered headboard wall. Build: Upholstered platform base on a recessed plinth; mattress block with 40 mm rounded edges; duvet/bed-runner layer draped 120 mm over the sides; 2–4 pillows generated from PILLOW sub-family. Headboard wall is a separate finish family. Size: 1980 × 1829 × H 450 mm; 1 instance(s); floor-standing. Materials: M_Velvet_Cream. | T38: SM_FF_BED_PLATFORM_1980x1830x450 | U38: SM_FF_MB_01 | V38: Yes | W38: 20–60k tris (hero)
A39: MB-02 | B39: Master bedroom | C39: Furniture | D39: Walnut side tables ×2 with marble tops | E39: SIDE_TABLE | F39: gen_side_table | G39: floor | H39: 2 | I39: 450 | J39: 450 | K39: 550 | L39: 3715 | M39: 4594 | N39: 0 | O39: 0 | P39: — | Q39: {"top_t": 25, "carcass": "box", "drawer_count": 1, "leg": "none", "top_material": "marble"} | R39: M_Walnut, M_Marble_Calacatta | S39: Walnut side tables ×2 with marble tops. Build: Box carcass with one drawer (3 mm shadow gap), separate stone/wood top slab with 3 mm edge bevel; optional brass legs (Ø16 tapered) when leg=brass. Size: 450 × 450 × H 550 mm; 2 instance(s); floor-standing. Materials: M_Walnut, M_Marble_Calacatta. | T39: SM_FF_SIDE_TABLE_450x450x550 | U39: SM_FF_MB_02 | V39: Yes | W39: 20–60k tris (hero)
A40: MB-03 | B40: Master bedroom | C40: Furniture | D40: 2 olive bouclé lounge chairs with bronze side table | E40: CHAIR_LOUNGE | F40: gen_chair_lounge | G40: floor | H40: 3 | I40: 760 | J40: 760 | K40: 800 | L40: 1100 | M40: 7650 | N40: 0 | O40: 180 | P40: S | Q40: {"seat_h": 400, "back_h": 800, "arm": "rounded", "leg": "tapered bronze", "leg_h": 150} | R40: M_Boucle_Olive, M_Boucle_Grey, M_Bronze_Dark, M_Foliage_Olive | S40: 2 olive bouclé lounge chairs with bronze side table. Build: Club/lounge chair: sculpted shell or box body with rounded arms, loose seat cushion, 4 tapered bronze legs fitted into a sub-frame plate (no gaps). Size: Ø760 × H 800 mm; 3 instance(s); floor-standing. Materials: M_Boucle_Olive, M_Boucle_Grey, M_Bronze_Dark, M_Foliage_Olive. Fit note: by the balcony glazing; access via the right-hand sliding panel. | T40: SM_FF_CHAIR_LOUNGE_760x760x800 | U40: SM_FF_MB_03 | V40: No | W40: 20–60k tris (hero) | X40: by the balcony glazing; access via the right-hand sliding panel
...

Sheet Placements
A1: Item_Code | B1: Instance | C1: Mesh_Asset | D1: X_mm | E1: Y_mm | F1: Z_mm | G1: Rot_Z_deg | H1: Footprint_L_mm | I1: Footprint_W_mm | J1: H_mm | K1: Object_Name
A2: UL-01 | B2: 1 | C2: SM_FF_CHAIR_BARREL_SWIVEL_820x820x760 | D2: 7550 | E2: 5750 | F2: 0 | G2: 90 | H2: 820 | I2: 820 | J2: 760 | K2: SM_FF_UL_01_01
A3: UL-01 | B3: 2 | C3: SM_FF_CHAIR_BARREL_SWIVEL_820x820x760 | D3: 7550 | E3: 6850 | F3: 0 | G3: 90 | H3: 820 | I3: 820 | J3: 760 | K3: SM_FF_UL_01_02
A4: UL-02 | B4: 1 | C4: SM_FF_TABLE_ROUND_700x700x400 | D4: 6750 | E4: 6300 | F4: 0 | G4: 0 | H4: 700 | I4: 700 | J4: 400 | K4: SM_FF_UL_02_01
A5: UL-03 | B5: 1 | C5: SM_FF_CONSOLE_1500x350x800 | D5: 8470 | E5: 8102 | F5: 0 | G5: 0 | H5: 1500 | I5: 350 | J5: 800 | K5: SM_FF_UL_03_01
A6: UL-04 | B6: 1 | C6: SM_FF_BOOKSHELF_LOW_1400x350x900 | D6: 8540 | E6: 4734 | F6: 0 | G6: 0 | H6: 1400 | I6: 350 | J6: 900 | K6: SM_FF_UL_04_01
A7: UL-05 | B7: 1 | C7: SM_FF_SOFA_LOVESEAT_1600x850x780 | D7: 5575 | E7: 6300 | F7: 0 | G7: 270 | H7: 1600 | I7: 850 | J7: 780 | K7: SM_FF_UL_05_01
A8: UL-06 | B8: 1 | C8: SM_FF_TABLE_DRUM_450x450x500 | D8: 5575 | E8: 5230 | F8: 0 | G8: 0 | H8: 450 | I8: 450 | J8: 500 | K8: SM_FF_UL_06_01
A9: UL-06 | B9: 2 | C9: SM_FF_TABLE_DRUM_450x450x500 | D9: 5575 | E9: 7370 | F9: 0 | G9: 0 | H9: 450 | I9: 450 | J9: 500 | K9: SM_FF_UL_06_02
A10: UL-07 | B10: 1 | C10: SM_FF_POUF_ROUND_450x450x420 | D10: 8150 | E10: 7680 | F10: 0 | G10: 0 | H10: 450 | I10: 450 | J10: 420 | K10: SM_FF_UL_07_01
A11: UL-07 | B11: 2 | C11: SM_FF_POUF_ROUND_450x450x420 | D11: 8790 | E11: 7680 | F11: 0 | G11: 0 | H11: 450 | I11: 450 | J11: 420 | K11: SM_FF_UL_07_02
A12: UL-08 | B12: 1 | C12: SM_FF_PLANTER_TREE_600x600x1800 | D12: 8900 | E12: 5600 | F12: 0 | G12: 0 | H12: 600 | I12: 600 | J12: 1800 | K12: SM_FF_UL_08_01
A13: UL-09 | B13: 1 | C13: SM_FF_ART_FRAME_1100x40x800 | D13: 8470 | E13: 8258 | F13: 1100 | G13: 180 | H13: 1140 | I13: 37 | J13: 800 | K13: SM_FF_UL_09_01
A14: UL-10 | B14: 1 | C14: SM_FF_ACCESSORY_250x250x150 | D14: 8000 | E14: 8100 | F14: auto (drop onto host) | G14: 0 | H14: 250 | I14: 250 | J14: 150 | K14: SM_FF_UL_10_01
A15: UL-11 | B15: 1 | C15: SM_FF_ACCESSORY_250x250x150 | D15: 6600 | E15: 6150 | F15: auto (drop onto host) | G15: 0 | H15: 250 | I15: 250 | J15: 150 | K15: SM_FF_UL_11_01
A16: UL-12 | B16: 1 | C16: SM_FF_ART_FRAME_1280x40x900 | D16: 8540 | E16: 4580 | F16: 1050 | G16: 0 | H16: 1280 | I16: 41 | J16: 900 | K16: SM_FF_UL_12_01
A17: UL-13 | B17: 1 | C17: SM_FF_ACCESSORY_250x250x150 | D17: 8540 | E17: 4734 | F17: auto (drop onto host) | G17: 0 | H17: 250 | I17: 250 | J17: 150 | K17: SM_FF_UL_13_01
A18: UL-14 | B18: 1 | C18: SM_FF_ACCESSORY_250x250x150 | D18: 6900 | E18: 6420 | F18: auto (drop onto host) | G18: 0 | H18: 250 | I18: 250 | J18: 150 | K18: SM_FF_UL_14_01
A19: UL-15 | B19: 1 | C19: SM_FF_ACCESSORY_250x250x150 | D19: 9050 | E19: 8100 | F19: auto (drop onto host) | G19: 0 | H19: 250 | I19: 250 | J19: 150 | K19: SM_FF_UL_15_01
A20: UL-16 | B20: 1 | C20: SM_FF_UL_WALL_PANEL_OGEE | D20: 6762 | E20: 6418 | F20: 0 | G20: 0 | H20: 5049 | I20: 3718 | J20: 2550 | K20: SM_FF_UL_16_01
A21: UL-17 | B21: 1 | C21: SM_FF_UL_FINISH_FLOOR | D21: 6762 | E21: 6418 | F21: 0 | G21: 0 | H21: 5049 | I21: 3718 | J21: 15 | K21: SM_FF_UL_17_01
A22: UL-18 | B22: 1 | C22: SM_FF_BALUSTRADE_GLASS_3720x40x1100 | D22: 9282 | E22: 6418 | F22: 0 | G22: 90 | H22: 3718 | I22: 35 | J22: 1100 | K22: SM_FF_UL_18_01
A23: UL-19 | B23: 1 | C23: SM_FF_WALL_FEATURE_PANEL_1640x30x2700 | D23: 8468 | E23: 8264 | F23: 0 | G23: 180 | H23: 1637 | I23: 27 | J23: 2700 | K23: SM_FF_UL_19_01
A24: UL-20 | B24: 1 | C24: SM_FF_UL_CEILING_TRAY | D24: 6700 | E24: 6325 | F24: 2950 | G24: 0 | H24: 3200 | I24: 2350 | J24: 200 | K24: SM_FF_UL_20_01
A25: UL-21 | B25: 1 | C25: SM_FF_INLAY_STRIP_3720x30x5 | D25: 9246 | E25: 6418 | F25: 0 | G25: 90 | H25: 3718 | I25: 32 | J25: 5 | K25: SM_FF_UL_21_01
A26: UL-22 | B26: 1 | C26: SM_FF_LIGHT_CHANDELIER_900x900x600 | D26: 6750 | E26: 6300 | F26: 2750 | G26: 0 | H26: 900 | I26: 900 | J26: 600 | K26: SM_FF_UL_22_01
A27: UL-23 | B27: 1 | C27: SM_FF_LIGHT_FLOOR_LAMP_350x350x1500 | D27: 5450 | E27: 7700 | F27: 0 | G27: 0 | H27: 350 | I27: 350 | J27: 1500 | K27: SM_FF_UL_23_01
A28: UL-24 | B28: 1 | C28: SM_FF_LIGHT_SCONCE_200x200x200 | D28: 7690 | E28: 8170 | F28: 1500 | G28: 0 | H28: 200 | I28: 200 | J28: 200 | K28: SM_FF_UL_24_01
A29: UL-24 | B29: 2 | C29: SM_FF_LIGHT_SCONCE_200x200x200 | D29: 9250 | E29: 8170 | F29: 1500 | G29: 0 | H29: 200 | I29: 200 | J29: 200 | K29: SM_FF_UL_24_02
A30: UL-25 | B30: 1 | C30: SM_FF_LIGHT_SPOT_700x40x80 | D30: 8550 | E30: 4620 | F30: 2750 | G30: 0 | H30: 700 | I30: 40 | J30: 80 | K30: SM_FF_UL_25_01
A31: UL-26 | B31: 1 | C31: SM_FF_RUG_2400x1700x12 | D31: 6750 | E31: 6300 | F31: 0 | G31: 0 | H31: 2400 | I31: 1700 | J31: 12 | K31: SM_FF_UL_26_01
A32: UL-27 | B32: 1 | C32: SM_FF_SOFT_SET_250x250x150 | D32: 5400 | E32: 6200 | F32: auto (drop onto host) | G32: 0 | H32: 250 | I32: 250 | J32: 150 | K32: SM_FF_UL_27_01
A33: UL-28 | B33: 1 | C33: SM_FF_SOFT_SET_250x250x150 | D33: 5400 | E33: 6900 | F33: auto (drop onto host) | G33: 0 | H33: 250 | I33: 250 | J33: 150 | K33: SM_FF_UL_28_01
A34: VO-01 | B34: 1 | C34: SM_FF_PLANTER_TROUGH_1500x250x400 | D34: 9162 | E34: 7050 | F34: 0 | G34: 90 | H34: 1500 | I34: 250 | J34: 400 | K34: SM_FF_VO_01_01
A35: VO-02 | B35: 1 | C35: SM_FF_ACCESSORY_1200x1200x150 | D35: 11350 | E35: 6400 | F35: auto (drop onto host) | G35: 0 | H35: 1200 | I35: 1200 | J35: 150 | K35: SM_FF_VO_02_01
A36: VO-03 | B36: 1 | C36: SM_FF_PLANT_SMALL_300x300x600 | D36: 9162 | E36: 7050 | F36: 0 | G36: 0 | H36: 300 | I36: 300 | J36: 600 | K36: SM_FF_VO_03_01
A37: VO-04 | B37: 1 | C37: SM_FF_BALUSTRADE_GLASS_3720x40x1100 | D37: 9290 | E37: 6418 | F37: 0 | G37: 270 | H37: 3718 | I37: 40 | J37: 1100 | K37: SM_FF_VO_04_01
A38: VO-05 | B38: 1 | C38: SM_FF_INLAY_STRIP_400x40x5 | D38: 9244 | E38: 5100 | F38: 0 | G38: 270 | H38: 400 | I38: 37 | J38: 5 | K38: SM_FF_VO_05_01
A39: VO-06 | B39: 1 | C39: SM_FF_CURTAIN_3640x40x6100 | D39: 12982 | E39: 6420 | F39: 0 | G39: 90 | H39: 3640 | I39: 45 | J39: 6100 | K39: SM_FF_VO_06_01
A40: VO-07 | B40: 1 | C40: SM_FF_LIGHT_LED_STRIP_3640x40x10 | D40: 9290 | E40: 6420 | F40: auto (drop onto host) | G40: 0 | H40: 3640 | I40: 40 | J40: 10 | K40: SM_FF_VO_07_01
...

Sheet Families
A1: Family | B1: Generator | C1: Host | D1: Default_H_mm | E1: Default_Params_JSON | F1: Construction recipe | G1: Items using
A2: BED_PLATFORM | B2: gen_bed | C2: floor | D2: 450 | E2: {"mattress_h": 250, "base_h": 200, "base_inset": 60, "leg": "recessed plinth 60", "bevel": 15, "duvet_drape": 120} | F2: Upholstered platform base on a recessed plinth; mattress block with 40 mm rounded edges; duvet/bed-runner layer draped 120 mm over the sides; 2–4 pillows generated from PILLOW sub-family. Headboard wall is a separate finish family. | G2: =COUNTIF(Items!$E:$E,A2) -> 3
A3: SIDE_TABLE | B3: gen_side_table | C3: floor | D3: 550 | E3: {"top_t": 25, "carcass": "box", "drawer_count": 1, "leg": "none", "top_material": "marble"} | F3: Box carcass with one drawer (3 mm shadow gap), separate stone/wood top slab with 3 mm edge bevel; optional brass legs (Ø16 tapered) when leg=brass. | G3: =COUNTIF(Items!$E:$E,A3) -> 3
A4: BENCH_UPHOLSTERED | B4: gen_bench | C4: floor | D4: 450 | E4: {"seat_t": 120, "leg_h": 180, "leg": "bronze sled", "piping": true} | F4: Upholstered seat block with piping on top edges, crowned top (+8 mm), on bronze sled legs (25×10 flat bar). | G4: =COUNTIF(Items!$E:$E,A4) -> 3
A5: CHAIR_BARREL_SWIVEL | B5: gen_chair_barrel | C5: floor | D5: 760 | E5: {"seat_h": 420, "back_h": 760, "shell_t": 90, "base": "swivel disc Ø450", "channels": 0} | F5: Lathe-swept barrel shell (260° wrap) solidified 90 mm, loose seat cushion, concealed swivel disc base; subdivision level 2. | G5: =COUNTIF(Items!$E:$E,A5) -> 1
A6: CHAIR_LOUNGE | B6: gen_chair_lounge | C6: floor | D6: 800 | E6: {"seat_h": 400, "back_h": 800, "arm": "rounded", "leg": "tapered bronze", "leg_h": 150} | F6: Club/lounge chair: sculpted shell or box body with rounded arms, loose seat cushion, 4 tapered bronze legs fitted into a sub-frame plate (no gaps). | G6: =COUNTIF(Items!$E:$E,A6) -> 3
A7: CHAIR_DESK | B7: gen_chair_desk | C7: floor | D7: 780 | E7: {"seat_h": 460, "back": "curved", "leg": "bronze 4-leg"} | F7: Compact bouclé desk chair: curved upholstered back, seat pad, 4 slim bronze legs with plate joints. | G7: =COUNTIF(Items!$E:$E,A7) -> 0
A8: SOFA_LOVESEAT | B8: gen_sofa | C8: floor | D8: 780 | E8: {"seat_h": 440, "seat_cushions": 2, "back_cushions": 2, "arm_w": 180, "plinth_inset": 60, "piping": true, "crown": 22, "back_tilt_deg": 12, "gap": 4} | F8: Same build as the GF sectional: recessed dark-bronze plinth, upholstered deck, frame with rolled top, crowned piped seat cushions, loose back cushions tilted 12°, 4 mm slot gaps, modifiers baked. | G8: =COUNTIF(Items!$E:$E,A8) -> 1
A9: TABLE_ROUND | B9: gen_table_round | C9: floor | D9: 420 | E9: {"top_t": 40, "base": "drum/pedestal", "edge": "eased 6"} | F9: Round top with eased edge on a drum or pedestal base; stone/travertine material with honed finish. | G9: =COUNTIF(Items!$E:$E,A9) -> 3
A10: TABLE_DRUM | B10: gen_table_drum | C10: floor | D10: 500 | E10: {"top_t": 20, "body": "walnut drum", "top_inset": 0} | F10: Cylindrical walnut drum body (vertical grain), marble top slab 20 mm with 2 mm bevel. | G10: =COUNTIF(Items!$E:$E,A10) -> 1
A11: CONSOLE | B11: gen_console | C11: floor | D11: 800 | E11: {"top_t": 40, "leg": "panel", "inlay": "brass 6 mm", "drawer_count": 0} | F11: Wall console: top slab + side panels or brass legs; optional solid-brass inlay strip routed 6 mm into the top; 20 mm wall stand-off. | G11: =COUNTIF(Items!$E:$E,A11) -> 2
A12: BOOKSHELF_LOW | B12: gen_bookshelf | C12: floor | D12: 900 | E12: {"shelves": 2, "bay_w": 480, "end_panels": "bronze-framed glass", "plinth": 60} | F12: Low walnut shelving: carcass 25 mm, adjustable shelves, bronze-framed glass end panels, recessed plinth. | G12: =COUNTIF(Items!$E:$E,A12) -> 1
A13: MEDIA_CONSOLE | B13: gen_media_console | C13: floor | D13: 450 | E13: {"type": "floating", "fronts": "flush", "tv_size_in": 75, "tv_recess_depth": 60} | F13: Slim walnut media console (floating or on brass legs) with flush push-open fronts; TV generated as a black-glass slab recessed into the host panel. | G13: =COUNTIF(Items!$E:$E,A13) -> 2
... A61: SOFT_SET | B61: gen_soft_set | C61: host | D61: 150 | E61: {"items": "auto"} | F61: Cushions / throws / bed runner / towels / bath mat generated from the soft-furnishing kit onto the host. | G61: =COUNTIF(Items!$E:$E,A61) -> 12
F62: Total items mapped to a family | G62: =SUM(G2:G61) -> 259

Sheet Materials
A1: Material | B1: Base colour (hex) | C1: Swatch | D1: Roughness | E1: Metallic | F1: Notes / texture set | G1: Used by items
A2: M_Walnut | B2: #5c3b26 | D2: 0.42 | E2: 0 | F2: Walnut veneer, hand-oiled; PBR set: BaseColor/Normal/Roughness, grain direction from object axis | G2: =COUNTIF(Items!$R:$R,"*"&A2&"*") -> 25
A3: M_Oak_Light | B3: #c3a27a | D3: 0.5 | E3: 0 | F3: Light oak veneer / engineered oak | G3: =COUNTIF(Items!$R:$R,"*"&A3&"*") -> 11
A4: M_Oak_Herringbone | B4: #b48e63 | D4: 0.45 | E4: 0 | F4: Engineered herringbone oak 600×90, hand-oiled | G4: =COUNTIF(Items!$R:$R,"*"&A4&"*") -> 4
A5: M_Teak_Outdoor | B5: #9a6a40 | D5: 0.6 | E5: 0 | F5: Teak / ipe outdoor grade | G5: =COUNTIF(Items!$R:$R,"*"&A5&"*") -> 10
A6: M_Velvet_Cream | B6: #e7ddcf | D6: 0.55 | E6: 0 | F6: Crushed velvet, sheen 1.0 — same as GF sectional | G6: =COUNTIF(Items!$R:$R,"*"&A6&"*") -> 10
A7: M_Velvet_Taupe | B7: #b5a48f | D7: 0.55 | E7: 0 | F7: Velvet benches / taupe headboards | G7: =COUNTIF(Items!$R:$R,"*"&A7&"*") -> 3
A8: M_Velvet_Greige | B8: #cfc6b8 | D8: 0.55 | E8: 0 | F8: Bedroom-2 headboard | G8: =COUNTIF(Items!$R:$R,"*"&A8&"*") -> 3
A9: M_Velvet_Charcoal | B9: #2b2b2e | D9: 0.5 | E9: 0 | F9: Accent cushions | G9: =COUNTIF(Items!$R:$R,"*"&A9&"*") -> 1
A10: M_Boucle_Grey | B10: #d9d3c9 | D10: 0.95 | E10: 0 | F10: Bouclé loop normal + sheen | G10: =COUNTIF(Items!$R:$R,"*"&A10&"*") -> 11
A11: M_Boucle_Olive | B11: #7f8a62 | D11: 0.95 | E11: 0 | F11: Olive bouclé | G11: =COUNTIF(Items!$R:$R,"*"&A11&"*") -> 2
A12: M_Marble_GreenVein | B12: #3f5a45 | D12: 0.18 | E12: 0 | F12: Green marble (master headboard flanks) | G12: =COUNTIF(Items!$R:$R,"*"&A12&"*") -> 1
A13: M_Marble_CalacattaViola | B13: #e7dce3 | D13: 0.2 | E13: 0 | F13: Calacatta Viola (bath tops, feature walls, niches) | G13: =COUNTIF(Items!$R:$R,"*"&A13&"*") -> 8
... A35: M_Moss_Preserved | B35: #5f7a5a | D35: 0.95 | E35: 0 | F35: Moss panel | G35: =COUNTIF(Items!$R:$R,"*"&A35&"*") -> 1

Sheet Gen_Prompts
A1: # | B1: Mesh family | C1: Prompt (paste into the Blender-connected Claude console)
A2: 1 | B2: BED_PLATFORM | C2: TASK: Generate the bed platform family — 3 item(s), meshes only. CONTEXT You are connected to a live Blender session. Generate MESH GEOMETRY ONLY for first-floor items, family by family, from first principles: write your own clean parametric Python generator for this family (one function, parameters in → mesh out) using bpy/bmesh. Do not use, import or look for any existing asset library or scripts. No materials, no material slots, no textures, no shaders, no lights. MESH RULES - Units: parameters in millimetres; Blender scene in metres (1 mm = 0.001). - Local frame of every asset: Z up, FRONT facing −Y, origin = bottom-centre of the footprint (floor items), back-centre on the wall plane (wall items), top-centre at the mount point (ceiling-hung items). Room-wide items (floors, wall skins, soffits, panel systems) are built directly in plan coordinates. - Quality: closed, manifold solids wherever the object is solid; consistent outward normals; no zero-area faces or loose vertices; no interpenetrating parts inside one asset; soft edges by real bevels / subdivision that you APPLY (no live modifiers left); scale applied (1,1,1); triangle budget ≈ 5–40k per furniture asset, ≤ 5k for small accessories. - Keep logical parts as separate named objects parented to the asset root (e.g. frame, cushion, top, legs, glass) so materials can be assigned later — but assign none. - UVs: add one UV map with a simple real-world box projection (1 UV unit = 1 m) so the mesh is ready for later texturing. Smooth shading with sharp edges marked above 30°. - Material words in item names (walnut, marble, velvet, brass…) identify the item only — ignore them for geometry. PLACEMENT RULES - Plan coordinates X, Y in mm on the first-floor plan (X east, Y north) → Blender X = X/1000, Y = Y/1000. - First-floor finished floor level FFL = +3.348 m. Z values are relative to FFL ("host" = snap onto the top of the object under that point). - Put the asset origin on the listed point, then rotate about Z by rot_z so the front faces the listed direction (S = 0°, E = 90°, N = 180°, W = 270°). - Items with several placements: build the mesh ONCE and place linked duplicates (shared mesh data). - Naming: asset root SM_FF_<CODE>_<NN> (e.g. SM_FF_UL_01_02); mesh data SM_FF_<FAMILY>_<CODE>. Collections: FF_Meshes › FF_<SpaceCode> (UL, VO, MB, MW, MT, B1, BW, BT, B2, B2T, LB, SB, ST, LL). - After placing, check bounding-box overlaps > 2 mm between new assets and with existing scene geometry; list them, do not move anything silently. REPORT AT THE END (table): code · built OK / failed · instances placed · triangle count · manifold yes/no · overlaps. Save a copy of the .blend as FF_<FAMILY>_meshes.blend (do not overwrite the open file). FAMILY GENERATOR — BED_PLATFORM Write a function build_bed_platform(**params) that returns the asset root. Geometry recipe: Platform base: rounded box (L×W×base_h) with 15 mm edge radius, set back base_inset from a recessed plinth (60 mm high, inset 60). Mattress: rounded box W−80 × L−80 × mattress_h, 40 mm corner radius, on the base. Duvet: thin surface (20 mm) over the mattress top, draped 120 mm down the sides and foot with soft folds (low-frequency displacement 4–6 mm), turned down 350 mm at the head. Pillows: 2–4 pillow volumes (pillow_w 700 × 450 × 160, crowned) leaning 15° at the head. Head is at +Y, foot (front) at −Y. Headboard walls are separate items. Default parameters (mm): {"mattress_h": 250, "base_h": 200, "base_inset": 60, "leg": "recessed plinth 60", "bevel": 15, "duvet_drape": 120, "H": 450} Host type: floor. ITEMS 1. MB-01 — Master bedroom — King bed 1829×1981 with full-height upholstered headboard wall size L×W×H: 1980 × 1829 × 450 mm | parameters: {"mattress_h": 250, "base_h": 200, "base_inset": 60, "leg": "recessed plinth 60", "bevel": 15, "duvet_drape": 120} placements: #01 X 2950 Y 5784 Z FFL+0 | front faces: W → rot_z 270° 2. B1-01 — Bedroom-1 — King bed 1829×1981 with walnut-slat headboard and taupe fabric panels size L×W×H: 1981 × 1829 × 450 mm | parameters: {"mattress_h": 250, "base_h": 200, "base_inset": 60, "leg": "recessed plinth 60", "bevel": 15, "duvet_drape": 120} placements: #01 X 9348 Y 1320 Z FFL+0 | front faces: N → rot_z 180° 3. B2-01 — Bedroom-2 (+ vestibule) — Queen bed 1524×1981 with greige velvet upholstered headboard and bronze trim size L×W×H: 1981 × 1524 × 450 mm | parameters: {"mattress_h": 250, "base_h": 200, "base_inset": 60, "leg": "recessed plinth 60", "bevel": 15, "duvet_drape": 120} placements: #01 X 9410 Y 9598 Z FFL+0 | front faces: N → rot_z 180° Build the generator, test it on the first item, then build and place all items in order. Ask me only if a placement point clearly falls outside the building.
A3: 2 | B3: SIDE_TABLE | C3: TASK: Generate the side table family — 3 item(s), meshes only. CONTEXT You are connected to a live Blender session. Generate MESH GEOMETRY ONLY for first-floor items, family by family, from first principles: write your own clean parametric Python generator for this family (one function, parameters in → mesh out) using bpy/bmesh. Do not use, import or look for any existing asset library or scripts. No materials, no material slots, no textures, no shaders, no lights. MESH RULES - Units: parameters in millimetres; Blender scene in metres (1 mm = 0.001). - Local frame of every asset: Z up, FRONT facing −Y, origin = bottom-centre of the footprint (floor items), back-centre on the wall plane (wall items), top-centre at the mount point (ceiling-hung items). Room-wide items (floors, wall skins, soffits, panel systems) are built directly in plan coordinates. - Quality: closed, manifold solids wherever the object is solid; consistent outward normals; no zero-area faces or loose vertices; no interpenetrating parts inside one asset; soft edges by real bevels / subdivision that you APPLY (no live modifiers left); scale applied (1,1,1); triangle budget ≈ 5–40k per furniture asset, ≤ 5k for small accessories. - Keep logical parts as separate named objects parented to the asset root (e.g. frame, cushion, top, legs, glass) so materials can be assigned later — but assign none. - UVs: add one UV map with a simple real-world box projection (1 UV unit = 1 m) so the mesh is ready for later texturing. Smooth shading with sharp edges marked above 30°. - Material words in item names (walnut, marble, velvet, brass…) identify the item only — ignore them for geometry. PLACEMENT RULES - Plan coordinates X, Y in mm on the first-floor plan (X east, Y north) → Blender X = X/1000, Y = Y/1000. - First-floor finished floor level FFL = +3.348 m. Z values are relative to FFL ("host" = snap onto the top of the object under that point). - Put the asset origin on the listed point, then rotate about Z by rot_z so the front faces the listed direction (S = 0°, E = 90°, N = 180°, W = 270°). - Items with several placements: build the mesh ONCE and place linked duplicates (shared mesh data). - Naming: asset root SM_FF_<CODE>_<NN> (e.g. SM_FF_UL_01_02); mesh data SM_FF_<FAMILY>_<CODE>. Collections: FF_Meshes › FF_<SpaceCode> (UL, VO, MB, MW, MT, B1, BW, BT, B2, B2T, LB, SB, ST, LL). - After placing, check bounding-box overlaps > 2 mm between new assets and with existing scene geometry; list them, do not move anything silently. REPORT AT THE END (table): code · built OK / failed · instances placed · triangle count · manifold yes/no · overlaps. Save a copy of the .blend as FF_<FAMILY>_meshes.blend (do not overwrite the open file). FAMILY GENERATOR — SIDE_TABLE Write a function build_side_table(**params) that returns the asset root. Geometry recipe: Carcass box L×W×(H−top_t) with a 3 mm shadow-gap drawer front (or door) on the −Y face; separate top slab top_t with 3 mm bevel, flush or 10 mm overhang. leg='brass': replace carcass with a top + 4 tapered round legs Ø16→Ø10 inset 40. Default parameters (mm): {"top_t": 25, "carcass": "box", "drawer_count": 1, "leg": "none", "top_material": "marble", "H": 550} Host type: floor. ITEMS 1. MB-02 — Master bedroom — Walnut side tables ×2 with marble tops size L×W×H: 450 × 450 × 550 mm | parameters: {"top_t": 25, "drawer_count": 1, "leg": "none"} placements: #01 X 3715 Y 4594 Z FFL+0; #02 X 3715 Y 6973 Z FFL+0 | front faces: any → rot_z 0° 2. B1-02 — Bedroom-1 — Walnut side tables ×2 with marble tops size L×W×H: 450 × 450 × 550 mm | parameters: {"top_t": 25, "drawer_count": 1, "leg": "none"} placements: #01 X 8158 Y 555 Z FFL+0; #02 X 10537 Y 555 Z FFL+0 | front faces: any → rot_z 0° 3. B2-02 — Bedroom-2 (+ vestibule) — Oak side tables ×2 on brass legs size L×W×H: 450 × 450 × 550 mm | parameters: {"top_t": 25, "drawer_count": 1, "leg": "default"} placements: #01 X 8373 Y 8832 Z FFL+0; #02 X 10447 Y 8832 Z FFL+0 | front faces: any → rot_z 0° Build the generator, test it on the first item, then build and place all items in order. Ask me only if a placement point clearly falls outside the building.
